<?xml version='1.0'?>
<sdf version='1.7'>
  <model name='A30_L25'>

    <include>
      <uri>model://SAR_Base</uri>
    </include>

    <link name='Leg_1'>
    <pose>23.8e-3 -23.8e-3 -1.6e-3 0 1.0472 -0.785</pose>
    <!--<pose>23.8e-3 -23.8e-3 -1.6e-3 0 1.0472 -0.785</pose>-->
    <inertial>
        <mass>2.40E-3</mass>
        <pose>2.32E-2 0 2.32E-3 0 0 0 </pose>
        <inertia>
        <ixx>5.29E-8</ixx>
        <ixy>0</ixy>
        <ixz>8.39E-8</ixz>
        <iyy>3.47E-7</iyy>
        <iyz>0</iyz>
        <izz>3.06E-7</izz>
        </inertia>
    </inertial>
    <gravity>1</gravity>
    <self_collide>1</self_collide>
    <visual name='Leg_Visual'>
        <pose>0 0 0 0 0 0</pose>
        <geometry>
        <mesh>
            <uri>model://Leg_Assemblies/meshes/Leg_Assembly_30_deg--25mm--Crazyflie.STL</uri>
            <scale>1 1 1</scale>
        </mesh>
        </geometry>
            <material>
                <!--Red-->
                <ambient>1.0 0.0 0.0 1</ambient>
                <diffuse>1.0 0.0 0.0 1</diffuse>
                <specular>0.1 0.1 0.1 1.0</specular>
            <lighting>1</lighting>
            </material>
    </visual>
    <collision name="Leg_Collision_1">
        <pose>26.9e-3 0 5.3e-3 0 0 0</pose>
        <geometry>
        <sphere>
            <radius>6.5e-3</radius>
        </sphere>
        </geometry>
    </collision>
    <sensor name='sensor_contact' type='contact'>
        <contact>
            <collision>Leg_Collision_1</collision>
        </contact>
    </sensor>
    <!--
    <sensor name="Contact_Sensor" type="contact">
        <update_rate>100.0</update_rate>
        <contact>
        <collision>Leg_Collision_1</collision>
        </contact>
    </sensor>
    <self_collide>1</self_collide>
    -->
    </link>

    <link name='Leg_2'>
    <pose>-23.8e-3 -23.8e-3 -1.6e-3 0 1.0472 -2.35</pose>
    <!--<pose>-23.8e-3 -23.8e-3 -1.6e-3 0 1.0472 -2.35</pose>-->
    <inertial>
        <mass>2.40E-3</mass>
        <pose>2.32E-2 0 2.32E-3 0 0 0 </pose>
        <inertia>
        <ixx>5.29E-8</ixx>
        <ixy>0</ixy>
        <ixz>8.39E-8</ixz>
        <iyy>3.47E-7</iyy>
        <iyz>0</iyz>
        <izz>3.06E-7</izz>
        </inertia>
    </inertial>
    <gravity>1</gravity>
    <self_collide>1</self_collide>
    <visual name='Leg_Visual'>
        <pose>0 0 0 0 0 0</pose>
        <geometry>
        <mesh>
            <uri>model://Leg_Assemblies/meshes/Leg_Assembly_30_deg--25mm--Crazyflie.STL</uri>
            <scale>1 1 1</scale>
        </mesh>
        </geometry>
            <material>
                <!--DarkGrey-->
                <ambient>0.175 0.175 0.175 1</ambient>
                <diffuse>0.175 0.175 0.175 1</diffuse>
                <specular>0.175 0.175 0.175 1.00</specular>
            <lighting>1</lighting>
            </material>
    </visual>
    <collision name="Leg_Collision_2">
        <pose>26.9e-3 0 5.3e-3 0 0 0</pose>
        <geometry>
        <sphere>
            <radius>6.5e-3</radius>
        </sphere>
        </geometry>
    </collision>
    <!--
    <sensor name="Contact_Sensor" type="contact">
        <update_rate>100.0</update_rate>
        <contact>
        <collision>Leg_Collision_2</collision>
        </contact>
    </sensor>
    <self_collide>1</self_collide>
    -->
    </link>

    <link name='Leg_3'>
    <pose>-23.8e-3 23.8e-3 -1.6e-3 0 1.0472 2.35</pose>
    <!--<pose>-23.8e-3 23.8e-3 -1.6e-3 0 1.0472 2.35</pose>-->
    <inertial>
        <mass>2.40E-3</mass>
        <pose>2.32E-2 0 2.32E-3 0 0 0 </pose>
        <inertia>
        <ixx>5.29E-8</ixx>
        <ixy>0</ixy>
        <ixz>8.39E-8</ixz>
        <iyy>3.47E-7</iyy>
        <iyz>0</iyz>
        <izz>3.06E-7</izz>
        </inertia>
    </inertial>
    <gravity>1</gravity>
    <self_collide>1</self_collide>
    <visual name='Leg_Visual'>
        <pose>0 0 0 0 0 0</pose>
        <geometry>
        <mesh>
            <uri>model://Leg_Assemblies/meshes/Leg_Assembly_30_deg--25mm--Crazyflie.STL</uri>
            <scale>1 1 1</scale>
        </mesh>
        </geometry>
            <material>
                <!--DarkGrey-->
                <ambient>0.175 0.175 0.175 1</ambient>
                <diffuse>0.175 0.175 0.175 1</diffuse>
                <specular>0.175 0.175 0.175 1.00</specular>
            <lighting>1</lighting>
            </material>
    </visual>
    <collision name="Leg_Collision_3">
        <pose>26.9e-3 0 5.3e-3 0 0 0</pose>
        <geometry>
        <sphere>
            <radius>6.5e-3</radius>
        </sphere>
        </geometry>
    </collision>
    <!--
    <sensor name="Contact_Sensor" type="contact">
        <update_rate>100.0</update_rate>
        <contact>
        <collision>Leg_Collision_3</collision>
        </contact>
    </sensor>
    <self_collide>1</self_collide>
    -->
    </link>

    <link name='Leg_4'>
    <pose>23.8e-3 23.8e-3 -1.6e-3 0 1.0472 0.785</pose>
    <!--<pose>23.8e-3 23.8e-3 -1.6e-3 0 1.0472 0.785</pose>-->
    <inertial>
        <mass>2.40E-3</mass>
        <pose>2.32E-2 0 2.32E-3 0 0 0 </pose>
        <inertia>
        <ixx>5.29E-8</ixx>
        <ixy>0</ixy>
        <ixz>8.39E-8</ixz>
        <iyy>3.47E-7</iyy>
        <iyz>0</iyz>
        <izz>3.06E-7</izz>
        </inertia>
    </inertial>
    <gravity>1</gravity>
    <self_collide>1</self_collide>
    <visual name='Leg_Visual'>
        <pose>0 0 0 0 0 0</pose>
        <geometry>
        <mesh>
            <uri>model://Leg_Assemblies/meshes/Leg_Assembly_30_deg--25mm--Crazyflie.STL</uri>
            <scale>1 1 1</scale>
        </mesh>
        </geometry>
            <material>
                <!--Red-->
                <ambient>1.0 0.0 0.0 1</ambient>
                <diffuse>1.0 0.0 0.0 1</diffuse>
                <specular>0.1 0.1 0.1 1.0</specular>
            <lighting>1</lighting>
            </material>
    </visual>
    <collision name="Leg_Collision_4">
        <pose>26.9e-3 0 5.3e-3 0 0 0</pose>
        <geometry>
        <sphere>
            <radius>6.5e-3</radius>
        </sphere>
        </geometry>
    </collision>
    <!--
    <sensor name="Contact_Sensor" type="contact">
        <update_rate>100.0</update_rate>
        <contact>
        <collision>Leg_Collision_4</collision>
        </contact>
    </sensor>
    <self_collide>1</self_collide>
    -->
    </link>


<!--In Byran's program spring_stiffness,damping are zero-->
    <joint name='Hinge_1_Joint' type='universal'>
    <parent>SAR_Base::SAR_Body</parent>
    <child>Leg_1</child>
    <pose>0 0 0 0 0.5236 0</pose>
    <axis>
        <xyz>0 1 0</xyz>
        <limit>
        <lower>-5</lower>
        <upper>5</upper>
        </limit>
        <dynamics>
        <spring_stiffness>800e-6</spring_stiffness>
        <damping>5e-6</damping>
        </dynamics>
    </axis>
    <axis2>
        <xyz>0 0 1</xyz>
        <limit>
        <lower>-5</lower>
        <upper>5</upper>
        </limit>
        <dynamics>
        <spring_stiffness>800e-6</spring_stiffness>
        <damping>5e-6</damping>
        </dynamics>
    </axis2>
    </joint>

    <joint name='Hinge_2_Joint' type='universal'>
    <parent>SAR_Base::SAR_Body</parent>
    <child>Leg_2</child>
    <pose>0 0 0 0 0.5236 0</pose>
    <axis>
        <xyz>0 1 0</xyz>
        <limit>
        <lower>-5</lower>
        <upper>5</upper>
        </limit>
        <dynamics>
        <spring_stiffness>800e-6</spring_stiffness>
        <damping>5e-6</damping>
        </dynamics>
    </axis>
    <axis2>
        <xyz>0 0 1</xyz>
        <limit>
        <lower>-5</lower>
        <upper>5</upper>
        </limit>
        <dynamics>
        <spring_stiffness>800e-6</spring_stiffness>
        <damping>5e-6</damping>
        </dynamics>
    </axis2>
    </joint>

    <joint name='Hinge_3_Joint' type='universal'>
    <parent>SAR_Base::SAR_Body</parent>
    <child>Leg_3</child>
    <pose>0 0 0 0 0.5236 0</pose>
    <axis>
        <xyz>0 1 0</xyz>
        <limit>
        <lower>-5</lower>
        <upper>5</upper>
        </limit>
        <dynamics>
        <spring_stiffness>800e-6</spring_stiffness>
        <damping>5e-6</damping>
        </dynamics>
    </axis>
    <axis2>
        <xyz>0 0 1</xyz>
        <limit>
        <lower>-5</lower>
        <upper>5</upper>
        </limit>
        <dynamics>
        <spring_stiffness>800e-6</spring_stiffness>
        <damping>5e-6</damping>
        </dynamics>
    </axis2>
    </joint>

    <joint name='Hinge_4_Joint' type='universal'>
    <parent>SAR_Base::SAR_Body</parent>
    <child>Leg_4</child>
    <pose>0 0 0 0 0.5236 0</pose>
    <axis>
        <xyz>0 1 0</xyz>
        <limit>
        <lower>-5</lower>
        <upper>5</upper>
        </limit>
        <dynamics>
        <spring_stiffness>800e-6</spring_stiffness>
        <damping>5e-6</damping>
        </dynamics>
    </axis>
    <axis2>
        <xyz>0 0 1</xyz>
        <limit>
        <lower>-5</lower>
        <upper>5</upper>
        </limit>
        <dynamics>
        <spring_stiffness>800e-6</spring_stiffness>
        <damping>5e-6</damping>
        </dynamics>
    </axis2>
    </joint>

    <plugin
        filename="/home/dlee/ros2_ws/install/sar_gazebo/lib/libSticky_Leg_Plugin.so"
        name="gz::sim::systems::Sticky_Leg_Plugin">
      <LegNumber>1</LegNumber>
      <LinkName>Leg_1</LinkName>
      <CollisionName>Leg_Collision_1</CollisionName>
      <JointName>Leg_1_Contact_Joint</JointName>
    </plugin>
<!--
    <plugin
        filename="/home/dlee/ros2_ws/install/sar_gazebo/lib/libSticky_Leg_Plugin.so"
        name="gz::sim::systems::Sticky_Leg_Plugin">
      <LegNumber>2</LegNumber>
      <LinkName>Leg_2</LinkName>
      <CollisionName>Leg_Collision_2</CollisionName>
      <JointName>Leg_2_Contact_Joint</JointName>
    </plugin>

    <plugin
        filename="/home/dlee/ros2_ws/install/sar_gazebo/lib/libSticky_Leg_Plugin.so"
        name="gz::sim::systems::Sticky_Leg_Plugin">
      <LegNumber>3</LegNumber>
      <LinkName>Leg_3</LinkName>
      <CollisionName>Leg_Collision_3</CollisionName>
      <JointName>Leg_3_Contact_Joint</JointName>
    </plugin>

    <plugin
        filename="/home/dlee/ros2_ws/install/sar_gazebo/lib/libSticky_Leg_Plugin.so"
        name="gz::sim::systems::Sticky_Leg_Plugin">
      <LegNumber>4</LegNumber>
      <LinkName>Leg_4</LinkName>
      <CollisionName>Leg_Collision_4</CollisionName>
      <JointName>Leg_4_Contact_Joint</JointName>
    </plugin>
-->
    <static>0</static>
    <allow_auto_disable>1</allow_auto_disable>
  </model>
</sdf>
