<?xml version='1.0'?>
<sdf version='1.7'>
  <model name='SAR_Base' canonical_link='SAR_Body'>
    <pose>0 0 0 0 0 0</pose>   <!--the pose is relative to the world by default-->

    <link name='SAR_Body'>
      <pose>0 0 0 0 0 0</pose>
      <inertial>
        <mass>693.0e-3</mass>
        <inertia>
          <ixx>3.17e-3</ixx>
          <ixy>0</ixy>
          <ixz>0</ixz>
          <iyy>2.71e-3</iyy>
          <iyz>0</iyz>
          <izz>5.27e-3</izz>
        </inertia>
        <pose>0 0 26.5e-3 0 0 0</pose>
      </inertial>
      <gravity>1</gravity>
      <self_collide>0</self_collide>
      <kinematic>0</kinematic>
      <enable_wind>0</enable_wind>

      <sensor name="imu" type="imu">
      <always_on>1</always_on>
      <update_rate>100</update_rate>
      <visualize>true</visualize>
      <topic>imu</topic>
      <enable_metrics>true</enable_metrics>
      </sensor>
<!--
      <visual name='Collision_Radius'>
        <pose>0 0 0 1.57 0 0</pose>
        <geometry>
          <cylinder>
            <length>250.0e-3</length>
            <radius>216.0e-3</radius>
          </cylinder>
        </geometry>
        <material>
        <ambient>1 1 1 0.2</ambient>
        <diffuse>1 1 1 0.2</diffuse>-->
        <!--<script>
          <uri>file://media/materials/scripts/gazebo.material</uri>
        </script>-->
<!--        <lighting>1</lighting>
      </material>
      </visual>
-->
      <visual name='SO_V5_Base_Assembly'>
        <pose>0 0 0 0 0 0</pose>
        <geometry>
          <mesh>
            <uri>model://SAR_Base/meshes/SO_V5_Base_Assembly.STL</uri>
            <scale>1 1 1</scale>
          </mesh>
        </geometry>
        <material>
            <!--DarkGrey-->
            <ambient>0.175 0.175 0.175 1</ambient>
            <diffuse>0.175 0.175 0.175 1</diffuse>
            <specular>0.175 0.175 0.175 1.00</specular>
        <lighting>1</lighting>
        </material>
      </visual>

      <visual name='SO_V5_Prop_Guards'>
        <pose>0 0 0 0 0 0</pose>
        <geometry>
          <mesh>
            <uri>model://SAR_Base/meshes/SO_V5_Prop_Guards.STL</uri>
            <scale>1 1 1</scale>
          </mesh>
        </geometry>
        <material>
            <!--White-->                    
            <ambient>1 1 1 1</ambient>
            <diffuse>1 1 1 1</diffuse>
            <specular>0.1 0.1 0.1 0.128</specular>
        <lighting>1</lighting>
        </material>
      </visual>

      <visual name='SO_V5_Prop_Guard_Standoffs'>
        <pose>0 0 0 0 0 0</pose>
        <geometry>
          <mesh>
            <uri>model://SAR_Base/meshes/SO_V5_Prop_Guard_Standoffs.STL</uri>
            <scale>1 1 1</scale>
          </mesh>
        </geometry>
        <material>
            <!--DarkGrey-->
            <ambient>0.175 0.175 0.175 1</ambient>
            <diffuse>0.175 0.175 0.175 1</diffuse>
            <specular>0.175 0.175 0.175 1.00</specular>
        <lighting>1</lighting>
        </material>
      </visual>

      <collision name='Body_Collision_Prop_1'>
        <pose>72.6e-3 -86.6e-3 20.5e-3 0 0 0</pose>
        <geometry>
          <cylinder>
            <length>41.0e-3</length>
            <radius>77.0e-3</radius>
          </cylinder>
        </geometry>
      </collision>

      <collision name='Body_Collision_Prop_2'>
        <pose>-72.6e-3 -86.6e-3 20.5e-3 0 0 0</pose>
        <geometry>
          <cylinder>
            <length>41.0e-3</length>
            <radius>77.0e-3</radius>
          </cylinder>
        </geometry>
      </collision>

      <collision name='Body_Collision_Prop_3'>
        <pose>-72.6e-3 86.6e-3 20.5e-3 0 0 0</pose>
        <geometry>
          <cylinder>
            <length>41.0e-3</length>
            <radius>77.0e-3</radius>
          </cylinder>
        </geometry>
      </collision>

      <collision name='Body_Collision_Prop_4'>
        <pose>72.6e-3 86.6e-3 20.5e-3 0 0 0</pose>
        <geometry>
          <cylinder>
            <length>41.0e-3</length>
            <radius>77.0e-3</radius>
          </cylinder>
        </geometry>
      </collision>

      <collision name='Body_Collision_Battery'>
        <pose>2.88e-3 0 35.0e-3 0 0 0</pose>
        <geometry>
          <box>
            <size>80.0e-3 45.0e-3 70.0e-3 </size>
          </box>
        </geometry>
      </collision>
    </link>

    <link name='Prop_1'>
      <inertial>
        <mass>1e-6</mass>
        <inertia>
          <ixx>1e-9</ixx>
          <ixy>0</ixy>
          <ixz>0</ixz>
          <iyy>1e-9</iyy>
          <iyz>0</iyz>
          <izz>1e-9</izz>
        </inertia>
        <pose>0 0 0 0 0 0</pose>
      </inertial>
      <pose>72.6e-3 -86.6e-3 28.0e-3 0 0 0</pose>
      <gravity>1</gravity>
      <self_collide>0</self_collide>
      <visual name='SO_V5_Prop_1'>
        <pose>0 0 0 0 0 0</pose>
        <geometry>
          <mesh>
            <uri>model://SAR_Base/meshes/SO_V5_Propeller.STL</uri>
            <scale>1 1 1</scale>
          </mesh>
        </geometry>
        <material>
            <!--Blue-->
            <ambient>0.0 0.0 1.0 1</ambient>
            <diffuse>0.0 0.0 1.0 1</diffuse>
        <lighting>1</lighting>
        </material>
      </visual>
    </link>

    <link name='Prop_2'>
      <inertial>
        <mass>1e-6</mass>
        <inertia>
          <ixx>1e-9</ixx>
          <ixy>0</ixy>
          <ixz>0</ixz>
          <iyy>1e-9</iyy>
          <iyz>0</iyz>
          <izz>1e-9</izz>
        </inertia>
        <pose>0 0 0 0 0 0</pose>
      </inertial>
      <pose>-72.6e-3 -86.6e-3 28.0e-3 0 0 0</pose>
      <gravity>1</gravity>
      <self_collide>0</self_collide>
      <visual name='SO_V5_Prop_2'>
        <pose>0 0 0 0 0 0</pose>
        <geometry>
          <mesh>
            <uri>model://SAR_Base/meshes/SO_V5_Propeller.STL</uri>
            <scale>1 1 1</scale>
          </mesh>
        </geometry>
        <material>
            <!--Blue-->
            <ambient>0.0 0.0 1.0 1</ambient>
            <diffuse>0.0 0.0 1.0 1</diffuse>
        <lighting>1</lighting>
        </material>
      </visual>
    </link>

    <link name='Prop_3'>
      <inertial>
        <mass>1e-6</mass>
        <inertia>
          <ixx>1e-9</ixx>
          <ixy>0</ixy>
          <ixz>0</ixz>
          <iyy>1e-9</iyy>
          <iyz>0</iyz>
          <izz>1e-9</izz>
        </inertia>
        <pose>0 0 0 0 0 0</pose>
      </inertial>
      <pose>-72.6e-3 86.6e-3 28.0e-3 0 0 0</pose>
      <gravity>1</gravity>
      <self_collide>0</self_collide>
      <visual name='SO_V5_Prop_2'>
        <pose>0 0 0 0 0 0</pose>
        <geometry>
          <mesh>
            <uri>model://SAR_Base/meshes/SO_V5_Propeller.STL</uri>
            <scale>1 1 1</scale>
          </mesh>
        </geometry>
        <material>
            <!--Blue-->
            <ambient>0.0 0.0 1.0 1</ambient>
            <diffuse>0.0 0.0 1.0 1</diffuse>
        <lighting>1</lighting>
        </material>
      </visual>
    </link>

    <link name='Prop_4'>
      <inertial>
        <mass>1e-6</mass>
        <inertia>
          <ixx>1e-9</ixx>
          <ixy>0</ixy>
          <ixz>0</ixz>
          <iyy>1e-9</iyy>
          <iyz>0</iyz>
          <izz>1e-9</izz>
        </inertia>
        <pose>0 0 0 0 0 0</pose>
      </inertial>
      <pose>72.6e-3 86.6e-3 28.0e-3 0 0 0</pose>
      <gravity>1</gravity>
      <self_collide>0</self_collide>
      <visual name='SO_V5_Prop_3'>
        <pose>0 0 0 0 0 0</pose>
        <geometry>
          <mesh>
            <uri>model://SAR_Base/meshes/SO_V5_Propeller.STL</uri>
            <scale>1 1 1</scale>
          </mesh>
        </geometry>
        <material>
            <!--Blue-->
            <ambient>0.0 0.0 1.0 1</ambient>
            <diffuse>0.0 0.0 1.0 1</diffuse>
        <lighting>1</lighting>
        </material>
      </visual>
    </link>

    <link name='Camera'>
        <inertial>
            <mass>1e-6</mass>
            <inertia>
            <ixx>1e-9</ixx>
            <ixy>0</ixy>
            <ixz>0</ixz>
            <iyy>1e-9</iyy>
            <iyz>0</iyz>
            <izz>1e-9</izz>
            </inertia>
            <pose>0 0 0 0 0 0</pose>
        </inertial>


    </link>

    <joint name='Prop_1_Joint' type='revolute'>
      <parent>SAR_Body</parent>
      <child>Prop_1</child>
      <pose>0 0 0 0 0 0</pose>
      <axis>
        <xyz>0 0 1</xyz>
        <limit>
          <lower>-1.79769e+308</lower>
          <upper>1.79769e+308</upper>
          <effort>-1</effort>
          <velocity>-1</velocity>
        </limit>
        <dynamics>
          <spring_reference>0</spring_reference>
          <spring_stiffness>0</spring_stiffness>
        </dynamics>
      </axis>
    </joint>

    <joint name='Prop_2_Joint' type='revolute'>
      <parent>SAR_Body</parent>
      <child>Prop_2</child>
      <pose>0 0 0 0 0 0</pose>
      <axis>
        <xyz>0 0 1</xyz>
        <limit>
          <lower>-1.79769e+308</lower>
          <upper>1.79769e+308</upper>
          <effort>-1</effort>
          <velocity>-1</velocity>
        </limit>
        <dynamics>
          <spring_reference>0</spring_reference>
          <spring_stiffness>0</spring_stiffness>
        </dynamics>
      </axis>
    </joint>

    <joint name='Prop_3_Joint' type='revolute'>
      <parent>SAR_Body</parent>
      <child>Prop_3</child>
      <pose>0 0 0 0 0 0</pose>
      <axis>
        <xyz>0 0 1</xyz>
        <limit>
          <lower>-1.79769e+308</lower>
          <upper>1.79769e+308</upper>
          <effort>-1</effort>
          <velocity>-1</velocity>
        </limit>
        <dynamics>
          <spring_reference>0</spring_reference>
          <spring_stiffness>0</spring_stiffness>
        </dynamics>
      </axis>
    </joint>

    <joint name='Prop_4_Joint' type='revolute'>
      <parent>SAR_Body</parent>
      <child>Prop_4</child>
      <pose>0 0 0 0 0 0</pose>
      <axis>
        <xyz>0 0 1</xyz>
        <limit>
          <lower>-1.79769e+308</lower>
          <upper>1.79769e+308</upper>
          <effort>-1</effort>
          <velocity>-1</velocity>
        </limit>
        <dynamics>
          <spring_reference>0</spring_reference>
          <spring_stiffness>0</spring_stiffness>
        </dynamics>
      </axis>
    </joint>


<!--  -->            
    <plugin
        filename="/home/dlee/ros2_ws/install/sar_gazebo/lib/libImu_Plugin.so"
        name="gz::sim::systems::Imu_Plugin">
    </plugin>
  
    <plugin
        filename="/home/dlee/ros2_ws/install/sar_gazebo/lib/libVicon_Plugin.so"
        name="gz::sim::systems::Vicon_Plugin">
        <!--<link_name>Prop_1</link_name>-->
        <link_name>SAR_Body</link_name>
    </plugin>
<!---->
    <plugin
        filename="/home/dlee/ros2_ws/install/sar_gazebo/lib/libMotor_Plugin.so"
        name="gz::sim::systems::Motor_Plugin">
        <Motor_Number>1</Motor_Number>
        <joint_name>Prop_1_Joint</joint_name>
        <link_name>Prop_1</link_name>
        <canonicallink_name>SAR_Body</canonicallink_name>
        <Turning_Direction>ccw</Turning_Direction>
        <Visual_Slowdown>200</Visual_Slowdown>                
    </plugin>

    <plugin
        filename="/home/dlee/ros2_ws/install/sar_gazebo/lib/libMotor_Plugin.so"
        name="gz::sim::systems::Motor_Plugin">
        <Motor_Number>2</Motor_Number>
        <joint_name>Prop_2_Joint</joint_name>
        <link_name>Prop_2</link_name>
        <canonicallink_name>SAR_Body</canonicallink_name>
        <Turning_Direction>cw</Turning_Direction>
        <Visual_Slowdown>200</Visual_Slowdown>                  
    </plugin>
    
    <plugin
        filename="/home/dlee/ros2_ws/install/sar_gazebo/lib/libMotor_Plugin.so"
        name="gz::sim::systems::Motor_Plugin">
        <Motor_Number>3</Motor_Number>
        <joint_name>Prop_3_Joint</joint_name>
        <link_name>Prop_3</link_name>
        <canonicallink_name>SAR_Body</canonicallink_name>
        <Turning_Direction>ccw</Turning_Direction>
        <Visual_Slowdown>200</Visual_Slowdown>                  
    </plugin>

    <plugin
        filename="/home/dlee/ros2_ws/install/sar_gazebo/lib/libMotor_Plugin.so"
        name="gz::sim::systems::Motor_Plugin">
        <Motor_Number>4</Motor_Number>
        <joint_name>Prop_4_Joint</joint_name>
        <link_name>Prop_4</link_name>
        <canonicallink_name>SAR_Body</canonicallink_name>
        <Turning_Direction>cw</Turning_Direction>
        <Visual_Slowdown>200</Visual_Slowdown>               
    </plugin>

    <static>0</static>
    <allow_auto_disable>1</allow_auto_disable>
  </model>
</sdf>
