<?xml version='1.0'?>
<sdf version='1.7'>
  <model name='A30_L200'>

    <include>
      <uri>model://SAR_Base</uri>
    </include>

    <link name='Leg_1'>
      <pose>18.5e-3 -18.5e-3 -4.0e-3 0 1.047 -0.785</pose>
      <inertial>
        <mass>2.47E-2</mass>
        <pose>1.35E-1 0 -1.20E-3 0 0 0 </pose>
        <inertia>
          <ixx>1.61E-6</ixx>
          <ixy>0</ixy>
          <ixz>0</ixz>
          <iyy>2.09E-4</iyy>
          <iyz>0</iyz>
          <izz>2.08E-4</izz>
        </inertia>
      </inertial>
      <gravity>1</gravity>
      <self_collide>1</self_collide>
      <visual name='Leg_Visual'>
        <pose>0 0 0 0 0 0</pose>
        <geometry>
          <mesh>
            <uri>model://Leg_Assemblies/meshes/Leg_Assembly_DH.STL</uri>
            <scale>1 1 1</scale>
          </mesh>
        </geometry>
          <material>
              <!--Red-->
              <ambient>1.0 0.0 0.0 1</ambient>
              <diffuse>1.0 0.0 0.0 1</diffuse>
              <specular>0.1 0.1 0.1 1.0</specular>
          <lighting>1</lighting>
          </material>
      </visual>
<!--
      <visual name='Collision_Radius_1'>
        <pose>104.5e-3 0 -1.9e-3 0 1.57 0</pose>
        <geometry>
          <cylinder>
            <length>209.0e-3</length>
            <radius>2.5e-3</radius>
          </cylinder>
        </geometry>
        <material>
        <ambient>1 1 1 0.2</ambient>
        <diffuse>1 1 1 0.2</diffuse>
        <lighting>1</lighting>
        </material>
      </visual>
-->
      <collision name="Leg_Collision_1">
        <pose>104.5e-3 0 -1.9e-3 0 1.57 0</pose>
        <geometry>
          <cylinder>
            <length>109.0e-3</length>
            <radius>2.5e-3</radius>
          </cylinder>
        </geometry>
      </collision>
<!--
      <collision name="Leg_Collision_1">
        <pose>210.0e-3 0 -1.9e-3 0 0 0</pose>
        <geometry>
          <sphere>
            <radius>13.9e-3</radius>
          </sphere>
        </geometry>
      </collision>
-->
<!--
      <sensor name='contact_sensor' type='contact'>
          <contact>
              <collision>Leg_Collision_1</collision>
              <topic>/SAR_Internal/Leg_Connections_1</topic>
          </contact>
          <always_on>1</always_on>
          <update_rate>100</update_rate>
      </sensor>
-->
      <self_collide>1</self_collide>
    </link>
<!---->
    <link name='Foot_1'>
      <pose>94.4e-3 -94.4e-3 -192.1e-3 0 1.047 -0.785</pose>
      <inertial>
        <mass>2.47E-2</mass>
        <pose>0 0 0 0 0 0 </pose>
      </inertial>
      <gravity>1</gravity>
      <self_collide>1</self_collide>
      <visual name='Foot_Visual'>
        <pose>0 0 0 0 0 0</pose>
        <geometry>
          <mesh>
            <uri>model://Leg_Assemblies/meshes/Leg_Foot_DH.STL</uri>
            <scale>1 1 1</scale>
          </mesh>
        </geometry>
          <material>
              <ambient>1.0 0.0 0.0 1</ambient>
              <diffuse>1.0 0.0 0.0 1</diffuse>
              <specular>0.1 0.1 0.1 1.0</specular>
          <lighting>1</lighting>
          </material>
      </visual>

      <visual name='Collision_Radius_Foot_1'>
        <pose>-7.34e-3 0 1.17e-3 0 0 0</pose>
        <geometry>
          <sphere>
            <radius>13.9e-3</radius>
          </sphere>
        </geometry>
        <material>
        <ambient>1 1 1 0.2</ambient>
        <diffuse>1 1 1 0.2</diffuse>
        <lighting>1</lighting>
        </material>
      </visual>

      <collision name="Foot_Collision_1">
        <pose>-7.34e-3 0 1.17e-3 0 0 0</pose>
        <geometry>
          <sphere>
            <radius>13.9e-3</radius>
          </sphere>
        </geometry>
      </collision>
      <sensor name='contact_sensor' type='contact'>
          <contact>
              <collision>Foot_Collision_1</collision>
              <topic>/SAR_Internal/Leg_Connections_1</topic>
          </contact>
          <always_on>1</always_on>
          <update_rate>100</update_rate>
      </sensor>
      <self_collide>1</self_collide>
    </link>

    <link name='Leg_2'>
      <pose>-18.5e-3 -18.5e-3 -4.0e-3 0 1.047 -2.35</pose>
      <inertial>
        <mass>2.47E-2</mass>
        <pose>1.35E-1 0 -1.20E-3 0 0 0 </pose>
        <inertia>
          <ixx>1.61E-6</ixx>
          <ixy>0</ixy>
          <ixz>0</ixz>
          <iyy>2.09E-4</iyy>
          <iyz>0</iyz>
          <izz>2.08E-4</izz>
        </inertia>
      </inertial>
      <gravity>1</gravity>
      <self_collide>1</self_collide>
      <visual name='Leg_Visual'>
        <pose>0 0 0 0 0 0</pose>
        <geometry>
          <mesh>
            <uri>model://Leg_Assemblies/meshes/Leg_Assembly_DH.STL</uri>
            <scale>1 1 1</scale>
          </mesh>
        </geometry>
          <material>
              <!--DarkGrey-->
              <ambient>0.175 0.175 0.175 1</ambient>
              <diffuse>0.175 0.175 0.175 1</diffuse>
              <specular>0.175 0.175 0.175 1.00</specular>
          <lighting>1</lighting>
          </material>
      </visual>

<!--
      <visual name='Collision_Radius_2'>
        <pose>104.5e-3 0 -1.9e-3 0 1.57 0</pose>
        <geometry>
          <cylinder>
            <length>209.0e-3</length>
            <radius>2.5e-3</radius>
          </cylinder>
        </geometry>
        <material>
        <ambient>1 1 1 0.2</ambient>
        <diffuse>1 1 1 0.2</diffuse>
        <lighting>1</lighting>
        </material>
      </visual>
-->
<!---->

      <collision name="Leg_Collision_2">
        <pose>104.5e-3 0 -1.9e-3 0 1.57 0</pose>
        <geometry>
          <cylinder>
            <length>109.0e-3</length>
            <radius>2.5e-3</radius>
          </cylinder>
        </geometry>
      </collision>

<!--
      <collision name="Leg_Collision_2">
        <pose>210.0e-3 0 -1.9e-3 0 0 0</pose>
        <geometry>
          <sphere>
            <radius>13.9e-3</radius>
          </sphere>
        </geometry>
      </collision>
-->
<!--
      <sensor name='contact_sensor' type='contact'>
          <contact>
              <collision>Leg_Collision_2</collision>
              <topic>/SAR_Internal/Leg_Connections_2</topic>
          </contact>
          <always_on>1</always_on>
          <update_rate>100</update_rate>
      </sensor>
-->
      <self_collide>1</self_collide>
    </link>
<!---->
    <link name='Foot_2'>
      <pose>-94.4e-3 -94.4e-3 -192.1e-3 0 1.047 -2.35</pose>
      <inertial>
        <mass>2.47E-2</mass>
        <pose>0 0 0 0 0 0 </pose>
        <inertia>
          <ixx>1.61E-6</ixx>
          <ixy>0</ixy>
          <ixz>0</ixz>
          <iyy>2.09E-4</iyy>
          <iyz>0</iyz>
          <izz>2.08E-4</izz>
        </inertia>
      </inertial>
      <gravity>1</gravity>
      <self_collide>1</self_collide>
      <visual name='Foot_Visual'>
        <pose>0 0 0 0 0 0</pose>
        <geometry>
          <mesh>
            <uri>model://Leg_Assemblies/meshes/Leg_Foot_DH.STL</uri>
            <scale>1 1 1</scale>
          </mesh>
        </geometry>
          <material>
              <ambient>0.175 0.175 0.175 1</ambient>
              <diffuse>0.175 0.175 0.175 1</diffuse>
              <specular>0.175 0.175 0.175 1.00</specular>
          <lighting>1</lighting>
          </material>
      </visual>

      <visual name='Collision_Radius_Foot_2'>
        <pose>-7.34e-3 0 1.17e-3 0 0 0</pose>
        <geometry>
          <sphere>
            <radius>13.9e-3</radius>
          </sphere>
        </geometry>
        <material>
        <ambient>1 1 1 0.2</ambient>
        <diffuse>1 1 1 0.2</diffuse>
        <lighting>1</lighting>
        </material>
      </visual>

      <collision name="Foot_Collision_2">
        <pose>-7.34e-3 0 1.17e-3 0 0 0</pose>
        <geometry>
          <sphere>
            <radius>13.9e-3</radius>
          </sphere>
        </geometry>
      </collision>
      <sensor name='contact_sensor' type='contact'>
          <contact>
              <collision>Foot_Collision_2</collision>
              <topic>/SAR_Internal/Leg_Connections_2</topic>
          </contact>
          <always_on>1</always_on>
          <update_rate>100</update_rate>
      </sensor>
      <self_collide>1</self_collide>
    </link>

    <link name='Leg_3'>
      <pose>-18.5e-3 18.5e-3 -4.0e-3 0 1.047 2.35</pose>
      <inertial>
        <mass>2.47E-2</mass>
        <pose>1.35E-1 0 -1.20E-3 0 0 0 </pose>
        <inertia>
          <ixx>1.61E-6</ixx>
          <ixy>0</ixy>
          <ixz>0</ixz>
          <iyy>2.09E-4</iyy>
          <iyz>0</iyz>
          <izz>2.08E-4</izz>
        </inertia>
      </inertial>
      <gravity>1</gravity>
      <self_collide>1</self_collide>
      <visual name='Leg_Visual'>
        <pose>0 0 0 0 0 0</pose>
        <geometry>
          <mesh>
            <uri>model://Leg_Assemblies/meshes/Leg_Assembly_DH.STL</uri>
            <scale>1 1 1</scale>
          </mesh>
        </geometry>
          <material>
              <!--DarkGrey-->
              <ambient>0.175 0.175 0.175 1</ambient>
              <diffuse>0.175 0.175 0.175 1</diffuse>
              <specular>0.175 0.175 0.175 1.00</specular>
          <lighting>1</lighting>
          </material>
      </visual>

<!--
      <visual name='Collision_Radius_3'>
        <pose>104.5e-3 0 -1.9e-3 0 1.57 0</pose>
        <geometry>
          <cylinder>
            <length>209.0e-3</length>
            <radius>2.5e-3</radius>
          </cylinder>
        </geometry>
        <material>
        <ambient>1 1 1 0.2</ambient>
        <diffuse>1 1 1 0.2</diffuse>
        <lighting>1</lighting>
        </material>
      </visual>
-->
<!---->
      <collision name="Leg_Collision_3">
        <pose>104.5e-3 0 -1.9e-3 0 1.57 0</pose>
        <geometry>
          <cylinder>
            <length>109.0e-3</length>
            <radius>2.5e-3</radius>
          </cylinder>
        </geometry>
      </collision>

<!--
      <collision name="Leg_Collision_3">
        <pose>210.0e-3 0 -1.9e-3 0 0 0</pose>
        <geometry>
          <sphere>
            <radius>13.9e-3</radius>
          </sphere>
        </geometry>
      </collision>
-->
<!--
      <sensor name='contact_sensor' type='contact'>
          <contact>
              <collision>Leg_Collision_3</collision>
              <topic>/SAR_Internal/Leg_Connections_3</topic>
          </contact>
          <always_on>1</always_on>
          <update_rate>100</update_rate>
      </sensor>
-->
      <self_collide>1</self_collide>
    </link>
<!---->
    <link name='Foot_3'>
      <pose>-94.4e-3 94.4e-3 -192.1e-3 0 1.047 2.35</pose>
      <inertial>
        <mass>2.47E-2</mass>
        <pose>0 0 0 0 0 0 </pose>
        <inertia>
          <ixx>1.61E-6</ixx>
          <ixy>0</ixy>
          <ixz>0</ixz>
          <iyy>2.09E-4</iyy>
          <iyz>0</iyz>
          <izz>2.08E-4</izz>
        </inertia>
      </inertial>
      <gravity>1</gravity>
      <self_collide>1</self_collide>
      <visual name='Foot_Visual'>
        <pose>0 0 0 0 0 0</pose>
        <geometry>
          <mesh>
            <uri>model://Leg_Assemblies/meshes/Leg_Foot_DH.STL</uri>
            <scale>1 1 1</scale>
          </mesh>
        </geometry>
          <material>
              <ambient>0.175 0.175 0.175 1</ambient>
              <diffuse>0.175 0.175 0.175 1</diffuse>
              <specular>0.175 0.175 0.175 1.00</specular>
          <lighting>1</lighting>
          </material>
      </visual>

      <visual name='Collision_Radius_Foot_3'>
        <pose>-7.34e-3 0 1.17e-3 0 0 0</pose>
        <geometry>
          <sphere>
            <radius>13.9e-3</radius>
          </sphere>
        </geometry>
        <material>
        <ambient>1 1 1 0.2</ambient>
        <diffuse>1 1 1 0.2</diffuse>
        <lighting>1</lighting>
        </material>
      </visual>

      <collision name="Foot_Collision_3">
        <pose>-7.34e-3 0 1.17e-3 0 0 0</pose>
        <geometry>
          <sphere>
            <radius>13.9e-3</radius>
          </sphere>
        </geometry>
      </collision>
      <sensor name='contact_sensor' type='contact'>
          <contact>
              <collision>Foot_Collision_3</collision>
              <topic>/SAR_Internal/Leg_Connections_3</topic>
          </contact>
          <always_on>1</always_on>
          <update_rate>100</update_rate>
      </sensor>
      <self_collide>1</self_collide>
    </link>

    <link name='Leg_4'>
      <pose>18.5e-3 18.5e-3 -4.0e-3 0 1.047 0.785</pose>
      <inertial>
        <mass>2.47E-2</mass>
        <pose>1.35E-1 0 -1.20E-3 0 0 0 </pose>
        <inertia>
          <ixx>1.61E-6</ixx>
          <ixy>0</ixy>
          <ixz>0</ixz>
          <iyy>2.09E-4</iyy>
          <iyz>0</iyz>
          <izz>2.08E-4</izz>
        </inertia>
      </inertial>
      <gravity>1</gravity>
      <self_collide>1</self_collide>
      <visual name='Leg_Visual'>
        <pose>0 0 0 0 0 0</pose>
        <geometry>
          <mesh>
            <uri>model://Leg_Assemblies/meshes/Leg_Assembly_DH.STL</uri>
            <scale>1 1 1</scale>
          </mesh>
        </geometry>
          <material>
              <!--Red-->
              <ambient>1.0 0.0 0.0 1</ambient>
              <diffuse>1.0 0.0 0.0 1</diffuse>
              <specular>0.1 0.1 0.1 1.0</specular>
          <lighting>1</lighting>
          </material>
      </visual>

<!--
      <visual name='Collision_Radius_4'>
        <pose>104.5e-3 0 -1.9e-3 0 1.57 0</pose>
        <geometry>
          <cylinder>
            <length>209.0e-3</length>
            <radius>2.5e-3</radius>
          </cylinder>
        </geometry>
        <material>
        <ambient>1 1 1 0.2</ambient>
        <diffuse>1 1 1 0.2</diffuse>
        <lighting>1</lighting>
        </material>
      </visual>
-->
<!---->
      <collision name="Leg_Collision_4">
        <pose>104.5e-3 0 -1.9e-3 0 1.57 0</pose>
        <geometry>
          <cylinder>
            <length>109.0e-3</length>
            <radius>2.5e-3</radius>
          </cylinder>
        </geometry>
      </collision>

<!--
      <collision name="Leg_Collision_4">
        <pose>210.0e-3 0 -1.9e-3 0 0 0</pose>
        <geometry>
          <sphere>
            <radius>13.9e-3</radius>
          </sphere>
        </geometry>
      </collision>
-->
<!--
      <sensor name='contact_sensor' type='contact'>
          <contact>
              <collision>Leg_Collision_4</collision>
              <topic>/SAR_Internal/Leg_Connections_4</topic>
          </contact>
          <always_on>1</always_on>
          <update_rate>100</update_rate>
      </sensor>
-->
      <self_collide>1</self_collide>
    </link>
<!---->
    <link name='Foot_4'>
      <pose>94.4e-3 94.4e-3 -192.1e-3 0 1.047 0.785</pose>
      <inertial>
        <mass>2.47E-2</mass>
        <pose>0 0 0 0 0 0 </pose>
        <inertia>
          <ixx>1.61E-6</ixx>
          <ixy>0</ixy>
          <ixz>0</ixz>
          <iyy>2.09E-4</iyy>
          <iyz>0</iyz>
          <izz>2.08E-4</izz>
        </inertia>
      </inertial>
      <gravity>1</gravity>
      <self_collide>1</self_collide>
      <visual name='Foot_Visual'>
        <pose>0 0 0 0 0 0</pose>
        <geometry>
          <mesh>
            <uri>model://Leg_Assemblies/meshes/Leg_Foot_DH.STL</uri>
            <scale>1 1 1</scale>
          </mesh>
        </geometry>
          <material>
              <ambient>1.0 0.0 0.0 1</ambient>
              <diffuse>1.0 0.0 0.0 1</diffuse>
              <specular>0.1 0.1 0.1 1.0</specular>
          <lighting>1</lighting>
          </material>
      </visual>

      <visual name='Collision_Radius_Foot_4'>
        <pose>-7.34e-3 0 1.17e-3 0 0 0</pose>
        <geometry>
          <sphere>
            <radius>13.9e-3</radius>
          </sphere>
        </geometry>
        <material>
        <ambient>1 1 1 0.2</ambient>
        <diffuse>1 1 1 0.2</diffuse>
        <lighting>1</lighting>
        </material>
      </visual>

      <collision name="Foot_Collision_4">
        <pose>-7.34e-3 0 1.17e-3 0 0 0</pose>
        <geometry>
          <sphere>
            <radius>13.9e-3</radius>
          </sphere>
        </geometry>
      </collision>
      <sensor name='contact_sensor' type='contact'>
          <contact>
              <collision>Foot_Collision_4</collision>
              <topic>/SAR_Internal/Leg_Connections_4</topic>
          </contact>
          <always_on>1</always_on>
          <update_rate>100</update_rate>
      </sensor>
      <self_collide>1</self_collide>
    </link>

    <joint name='Hinge_1_Joint' type='universal'>
      <parent>SAR_Base::SAR_Body</parent>
      <child>Leg_1</child>
      <pose>0 0 0 0 0.5236 0</pose>
      <axis>
        <xyz>0 1 0</xyz>
        <limit>
          <lower>0.0</lower>
          <upper>1.309</upper>
        </limit>
        <dynamics>
          <spring_stiffness>5.0</spring_stiffness>
          <damping>0.3</damping>
        </dynamics>
      </axis>
      <axis2>
        <xyz>0 0 1</xyz>
        <limit>
          <lower>-0.349</lower>
          <upper>0.349</upper>
        </limit>
        <dynamics>
          <spring_stiffness>5.0</spring_stiffness>
          <damping>0.7</damping>
        </dynamics>
      </axis2>
    </joint>
<!---->
    <joint name='Ball_1_Joint' type='ball'>
      <parent>Leg_1</parent>
      <child>Foot_1</child>
      <pose>0 0 0 0 0 0</pose>
      <axis>
        <xyz>1 0 0</xyz>
        <limit>
          <lower>-1e16</lower>
          <upper>1e16</upper>
        </limit>
        <dynamics>
          <damping>0.01</damping>
        </dynamics>
      </axis>
    </joint>

    <joint name='Hinge_2_Joint' type='universal'>
      <parent>SAR_Base::SAR_Body</parent>
      <child>Leg_2</child>
      <pose>0 0 0 0 0.5236 0</pose>
      <axis>
        <xyz>0 1 0</xyz>
        <limit>
          <lower>0.0</lower>
          <upper>1.309</upper>
        </limit>
        <dynamics>
          <spring_stiffness>5.0</spring_stiffness>
          <damping>0.3</damping>
        </dynamics>
      </axis>
      <axis2>
        <xyz>0 0 1</xyz>
        <limit>
          <lower>-0.349</lower>
          <upper>0.349</upper>
        </limit>
        <dynamics>
          <spring_stiffness>5.0</spring_stiffness>
          <damping>0.7</damping>
        </dynamics>
      </axis2>
    </joint>
<!---->
    <joint name='Ball_2_Joint' type='ball'>
      <parent>Leg_2</parent>
      <child>Foot_2</child>
      <pose>0 0 0 0 0 0</pose>
      <axis>
        <xyz>1 0 0</xyz>
        <limit>
          <lower>-1e16</lower>
          <upper>1e16</upper>
        </limit>
        <dynamics>
          <damping>0.01</damping>
        </dynamics>
      </axis>
    </joint>

    <joint name='Hinge_3_Joint' type='universal'>
      <parent>SAR_Base::SAR_Body</parent>
      <child>Leg_3</child>
      <pose>0 0 0 0 0.5236 0</pose>
      <axis>
        <xyz>0 1 0</xyz>
        <limit>
          <lower>0.0</lower>
          <upper>1.309</upper>
        </limit>
        <dynamics>
          <spring_stiffness>5.0</spring_stiffness>
          <damping>0.3</damping>
        </dynamics>
      </axis>
      <axis2>
        <xyz>0 0 1</xyz>
        <limit>
          <lower>-0.349</lower>
          <upper>0.349</upper>
        </limit>
        <dynamics>
          <spring_stiffness>5.0</spring_stiffness>
          <damping>0.7</damping>
        </dynamics>
      </axis2>
    </joint>
<!---->
    <joint name='Ball_3_Joint' type='ball'>
      <parent>Leg_3</parent>
      <child>Foot_3</child>
      <pose>0 0 0 0 0 0</pose>
      <axis>
        <xyz>1 0 0</xyz>
        <limit>
          <lower>-1e16</lower>
          <upper>1e16</upper>
        </limit>
        <dynamics>
          <damping>0.01</damping>
        </dynamics>
      </axis>
    </joint>

    <joint name='Hinge_4_Joint' type='universal'>
      <parent>SAR_Base::SAR_Body</parent>
      <child>Leg_4</child>
      <pose>0 0 0 0 0.5236 0</pose>
      <axis>
        <xyz>0 1 0</xyz>
        <limit>
          <lower>0.0</lower>
          <upper>1.309</upper>
        </limit>
        <dynamics>
          <spring_stiffness>5.0</spring_stiffness>
          <damping>0.3</damping>
        </dynamics>
      </axis>
      <axis2>
        <xyz>0 0 1</xyz>
        <limit>
          <lower>-0.349</lower>
          <upper>0.349</upper>
        </limit>
        <dynamics>
          <spring_stiffness>5.0</spring_stiffness>
          <damping>0.7</damping>
        </dynamics>
      </axis2>
    </joint>
<!---->
    <joint name='Ball_4_Joint' type='ball'>
      <parent>Leg_4</parent>
      <child>Foot_4</child>
      <pose>0 0 0 0 0 0</pose>
      <axis>
        <xyz>1 0 0</xyz>
        <limit>
          <lower>-1e16</lower>
          <upper>1e16</upper>
        </limit>
        <dynamics>
          <damping>0.01</damping>
        </dynamics>
      </axis>
    </joint>

<!--
    <plugin
        filename="/home/dlee/ros2_ws/install/sar_gazebo/lib/libSticky_Leg_Plugin.so"
        name="gz::sim::systems::Sticky_Leg_Plugin">
      <LegNumber>1</LegNumber>
      <LinkName>Foot_1</LinkName>
      <CollisionName>Foot_Collision_1</CollisionName>
      <JointName>Foot_1_Contact_Joint</JointName>


      <child_model>A30_L200</child_model>
      <child_link>Foot_1</child_link>
    </plugin>
-->
<!--
    <plugin
        filename="/home/dlee/ros2_ws/install/sar_gazebo/lib/libSticky_Leg_Plugin.so"
        name="gz::sim::systems::Sticky_Leg_Plugin">
      <LegNumber>2</LegNumber>
      <LinkName>Leg_2</LinkName>
      <CollisionName>Leg_Collision_2</CollisionName>
      <JointName>Leg_2_Contact_Joint</JointName>

      <child_model>A30_L200</child_model>
      <child_link>Leg_2</child_link>
    </plugin>

    <plugin
        filename="/home/dlee/ros2_ws/install/sar_gazebo/lib/libSticky_Leg_Plugin.so"
        name="gz::sim::systems::Sticky_Leg_Plugin">
      <LegNumber>3</LegNumber>
      <LinkName>Leg_3</LinkName>
      <CollisionName>Leg_Collision_3</CollisionName>
      <JointName>Leg_3_Contact_Joint</JointName>

      <child_model>A30_L200</child_model>
      <child_link>Leg_3</child_link>
    </plugin>

    <plugin
        filename="/home/dlee/ros2_ws/install/sar_gazebo/lib/libSticky_Leg_Plugin.so"
        name="gz::sim::systems::Sticky_Leg_Plugin">
      <LegNumber>4</LegNumber>
      <LinkName>Leg_4</LinkName>
      <CollisionName>Leg_Collision4</CollisionName>
      <JointName>Leg_4_Contact_Joint</JointName>

      <child_model>A30_L200</child_model>
      <child_link>Leg_4</child_link>
    </plugin>
-->

    <static>0</static>
    <allow_auto_disable>1</allow_auto_disable>
  </model>
</sdf>
