<?xml version="1.0" ?>
<sdf version="1.10">



    <world name="sar_world_2">
        <physics name="1ms" type="ignored">
            <max_step_size>0.001</max_step_size>
            <real_time_factor>1.0</real_time_factor>
        </physics>

        <plugin
            filename="gz-sim-physics-system"
            name="gz::sim::systems::Physics">
        </plugin>

        <plugin
            filename="gz-sim-scene-broadcaster-system"
            name="gz::sim::systems::SceneBroadcaster">
        </plugin>

        <plugin
            filename="gz-sim-user-commands-system"
            name="gz::sim::systems::UserCommands">
        </plugin>

        <plugin
            filename="gz-sim-contact-system"
            name="gz::sim::systems::Contact">
        </plugin>

        <plugin
        filename="gz-sim-sensors-system"
        name="gz::sim::systems::Sensors">
        <render_engine>ogre2</render_engine>
        </plugin>                    
        <!-- 
        <plugin filename="/home/dlee/ros2_ws/install/sar_gazebo/lib/libMyStstemPlugin.so" name="MySystemPlugin">
        </plugin>-->


        <!-- Other world elements -->
        <gui fullscreen="0">
            <!-- 3D scene -->
            <plugin filename="GzScene3D" name="3D View">
                <gz-gui>
                <title>3D View</title>
                <property type="bool" key="showTitleBar">false</property>
                <property type="string" key="state">docked</property>
                </gz-gui>

                <engine>ogre2</engine>
                <scene>scene</scene>
                <ambient_light>0.4 0.4 0.4</ambient_light>
                <background_color>0.8 0.8 0.8</background_color>
            </plugin>

            <!-- World control -->
            <plugin filename="WorldControl" name="World control">
                <gz-gui>
                    <title>World control</title>
                    <property type="bool" key="showTitleBar">false</property>
                    <property type="bool" key="resizable">false</property>
                    <property type="double" key="height">72</property>
                    <property type="double" key="width">121</property>
                    <property type="double" key="z">1</property>

                    <property type="string" key="state">floating</property>
                    <anchors target="3D View">
                    <line own="left" target="left"/>
                    <line own="bottom" target="bottom"/>
                    </anchors>
                </gz-gui>

                <play_pause>true</play_pause>
                <step>true</step>
                <start_paused>true</start_paused>
                <service>/world/world_demo/control</service>
                <stats_topic>/world/world_demo/stats</stats_topic>
            </plugin>

            <!-- World statistics -->
            <plugin filename="WorldStats" name="World stats">
                <gz-gui>
                    <title>World stats</title>
                    <property type="bool" key="showTitleBar">false</property>
                    <property type="bool" key="resizable">false</property>
                    <property type="double" key="height">110</property>
                    <property type="double" key="width">290</property>
                    <property type="double" key="z">1</property>

                    <property type="string" key="state">floating</property>
                    <anchors target="3D View">
                    <line own="right" target="right"/>
                    <line own="bottom" target="bottom"/>
                    </anchors>
                </gz-gui>

                <sim_time>true</sim_time>
                <real_time>true</real_time>
                <real_time_factor>true</real_time_factor>
                <iterations>true</iterations>
                <topic>/world/world_demo/stats</topic>

            </plugin>
            
            <!-- Entity tree -->
            <plugin filename="EntityTree" name="Entity tree">
            </plugin>
            
        </gui>

        <light type="directional" name="sun">
            <cast_shadows>true</cast_shadows>
            <pose>0 0 10 0 0 0</pose>
            <diffuse>0.8 0.8 0.8 1</diffuse>
            <specular>0.2 0.2 0.2 1</specular>
            <attenuation>
                <range>1000</range>
                <constant>0.9</constant>
                <linear>0.01</linear>
                <quadratic>0.001</quadratic>
            </attenuation>
            <direction>-0.5 0.1 -0.9</direction>
        </light>
<!--
        <model name="Ground_Plane">
            <static>1</static>
            <link name="Ground_Link">
                <pose>0 0 -0.3 0 0 0</pose>
                <inertial>
                    <mass>1000</mass>
                    <pose>0 0 0 0 0 0</pose>
                    <inertia>
                    <ixx>500</ixx>
                    <ixy>0</ixy>
                    <ixz>0</ixz>
                    <iyy>500</iyy>
                    <iyz>0</iyz>
                    <izz>1000</izz>
                    </inertia>
                </inertial>
                <self_collide>0</self_collide>
                <enable_wind>0</enable_wind>
                <kinematic>0</kinematic>
                <gravity>0</gravity>                
                <collision name="collision">
                    <geometry>
                        <box>
                            <size>8 8 0.1</size>
                        </box>
                    </geometry>
                </collision>
                <visual name="visual">
                    <geometry>
                        <box>
                            <size>8 8 0.1</size>
                        </box>
                    </geometry>
                    <material>
                    <pbr>
                        <metal>
                        <albedo_map>models/Ground_Surface/Configs/Desert_Pattern/Ground_Texture/Images/desert_sand.jpg</albedo_map>
                        </metal>
                    </pbr>
                    <ambient>1 1 1 1</ambient>
                    <diffuse>1 1 1 1</diffuse>
                    <specular>0.5 0.5 0.5 1</specular>
                    </material>
                </visual>
                </link>
        </model>
-->
        <model name='SAR_Base' canonical_link='SAR_Body'>
            <pose>0 0 0 0 0 0</pose>   <!--the pose is relative to the world by default-->

            <link name='SAR_Body'>
            <pose>0 0 0 0 0 0</pose>
            <inertial>
                <mass>693.0e-3</mass>
                <inertia>
                <ixx>3.17e-3</ixx>
                <ixy>0</ixy>
                <ixz>0</ixz>
                <iyy>2.71e-3</iyy>
                <iyz>0</iyz>
                <izz>5.27e-3</izz>
                </inertia>
                <pose>0 0 26.5e-3 0 0 0</pose>
            </inertial>
            <gravity>1</gravity>
            <self_collide>0</self_collide>
            <kinematic>0</kinematic>
            <enable_wind>0</enable_wind>

            <sensor name="imu" type="imu">
            <always_on>1</always_on>
            <update_rate>100</update_rate>
            <visualize>true</visualize>
            <topic>imu</topic>
            <enable_metrics>true</enable_metrics>
            </sensor>

            <visual name='Collision_Radius'>
                <pose>0 0 0 1.57 0 0</pose>
                <geometry>
                <cylinder>
                    <length>250.0e-3</length>
                    <radius>216.0e-3</radius>
                </cylinder>
                </geometry>
                <material>
                <ambient>1 1 1 0.2</ambient>
                <diffuse>1 1 1 0.2</diffuse>
                <!--<script>
                <uri>file://media/materials/scripts/gazebo.material</uri>
                </script>-->
                <lighting>1</lighting>
            </material>
            </visual>

            <visual name='SO_V5_Base_Assembly'>
                <pose>0 0 0 0 0 0</pose>
                <geometry>
                <mesh>
                    <uri>models/Source_One_V5/SAR_Base/meshes/SO_V5_Base_Assembly.STL</uri>
                    <scale>1 1 1</scale>
                </mesh>
                </geometry>
                <material>
                    <!--DarkGrey-->
                    <ambient>0.175 0.175 0.175 1</ambient>
                    <diffuse>0.175 0.175 0.175 1</diffuse>
                    <specular>0.175 0.175 0.175 1.00</specular>
                <lighting>1</lighting>
                </material>
            </visual>

            <visual name='SO_V5_Prop_Guards'>
                <pose>0 0 0 0 0 0</pose>
                <geometry>
                <mesh>
                    <uri>models/Source_One_V5/SAR_Base/meshes/SO_V5_Prop_Guards.STL</uri>
                    <scale>1 1 1</scale>
                </mesh>
                </geometry>
                <material>
                    <!--White-->                    
                    <ambient>1 1 1 1</ambient>
                    <diffuse>1 1 1 1</diffuse>
                    <specular>0.1 0.1 0.1 0.128</specular>
                <lighting>1</lighting>
                </material>
            </visual>

            <visual name='SO_V5_Prop_Guard_Standoffs'>
                <pose>0 0 0 0 0 0</pose>
                <geometry>
                <mesh>
                    <uri>models/Source_One_V5/SAR_Base/meshes/SO_V5_Prop_Guard_Standoffs.STL</uri>
                    <scale>1 1 1</scale>
                </mesh>
                </geometry>
                <material>
                    <!--DarkGrey-->
                    <ambient>0.175 0.175 0.175 1</ambient>
                    <diffuse>0.175 0.175 0.175 1</diffuse>
                    <specular>0.175 0.175 0.175 1.00</specular>
                <lighting>1</lighting>
                </material>
            </visual>

            <collision name='Body_Collision_Prop_1'>
                <pose>72.6e-3 -86.6e-3 20.5e-3 0 0 0</pose>
                <geometry>
                <cylinder>
                    <length>41.0e-3</length>
                    <radius>77.0e-3</radius>
                </cylinder>
                </geometry>
            </collision>

            <collision name='Body_Collision_Prop_2'>
                <pose>-72.6e-3 -86.6e-3 20.5e-3 0 0 0</pose>
                <geometry>
                <cylinder>
                    <length>41.0e-3</length>
                    <radius>77.0e-3</radius>
                </cylinder>
                </geometry>
            </collision>

            <collision name='Body_Collision_Prop_3'>
                <pose>-72.6e-3 86.6e-3 20.5e-3 0 0 0</pose>
                <geometry>
                <cylinder>
                    <length>41.0e-3</length>
                    <radius>77.0e-3</radius>
                </cylinder>
                </geometry>
            </collision>

            <collision name='Body_Collision_Prop_4'>
                <pose>72.6e-3 86.6e-3 20.5e-3 0 0 0</pose>
                <geometry>
                <cylinder>
                    <length>41.0e-3</length>
                    <radius>77.0e-3</radius>
                </cylinder>
                </geometry>
            </collision>

            <collision name='Body_Collision_Battery'>
                <pose>2.88e-3 0 35.0e-3 0 0 0</pose>
                <geometry>
                <box>
                    <size>80.0e-3 45.0e-3 70.0e-3 </size>
                </box>
                </geometry>
            </collision>
            </link>

            <link name='Prop_1'>
            <inertial>
                <mass>1e-6</mass>
                <inertia>
                <ixx>1e-9</ixx>
                <ixy>0</ixy>
                <ixz>0</ixz>
                <iyy>1e-9</iyy>
                <iyz>0</iyz>
                <izz>1e-9</izz>
                </inertia>
                <pose>0 0 0 0 0 0</pose>
            </inertial>
            <pose>72.6e-3 -86.6e-3 28.0e-3 0 0 0</pose>
            <gravity>1</gravity>
            <self_collide>0</self_collide>
            <visual name='SO_V5_Prop_1'>
                <pose>0 0 0 0 0 0</pose>
                <geometry>
                <mesh>
                    <uri>models/Source_One_V5/SAR_Base/meshes/SO_V5_Propeller.STL</uri>
                    <scale>1 1 1</scale>
                </mesh>
                </geometry>
                <material>
                    <!--Blue-->
                    <ambient>0.0 0.0 1.0 1</ambient>
                    <diffuse>0.0 0.0 1.0 1</diffuse>
                <lighting>1</lighting>
                </material>
            </visual>
            </link>

            <link name='Prop_2'>
            <inertial>
                <mass>1e-6</mass>
                <inertia>
                <ixx>1e-9</ixx>
                <ixy>0</ixy>
                <ixz>0</ixz>
                <iyy>1e-9</iyy>
                <iyz>0</iyz>
                <izz>1e-9</izz>
                </inertia>
                <pose>0 0 0 0 0 0</pose>
            </inertial>
            <pose>-72.6e-3 -86.6e-3 28.0e-3 0 0 0</pose>
            <gravity>1</gravity>
            <self_collide>0</self_collide>
            <visual name='SO_V5_Prop_2'>
                <pose>0 0 0 0 0 0</pose>
                <geometry>
                <mesh>
                    <uri>models/Source_One_V5/SAR_Base/meshes/SO_V5_Propeller.STL</uri>
                    <scale>1 1 1</scale>
                </mesh>
                </geometry>
                <material>
                    <!--Blue-->
                    <ambient>0.0 0.0 1.0 1</ambient>
                    <diffuse>0.0 0.0 1.0 1</diffuse>
                <lighting>1</lighting>
                </material>
            </visual>
            </link>

            <link name='Prop_3'>
            <inertial>
                <mass>1e-6</mass>
                <inertia>
                <ixx>1e-9</ixx>
                <ixy>0</ixy>
                <ixz>0</ixz>
                <iyy>1e-9</iyy>
                <iyz>0</iyz>
                <izz>1e-9</izz>
                </inertia>
                <pose>0 0 0 0 0 0</pose>
            </inertial>
            <pose>-72.6e-3 86.6e-3 28.0e-3 0 0 0</pose>
            <gravity>1</gravity>
            <self_collide>0</self_collide>
            <visual name='SO_V5_Prop_2'>
                <pose>0 0 0 0 0 0</pose>
                <geometry>
                <mesh>
                    <uri>models/Source_One_V5/SAR_Base/meshes/SO_V5_Propeller.STL</uri>
                    <scale>1 1 1</scale>
                </mesh>
                </geometry>
                <material>
                    <!--Blue-->
                    <ambient>0.0 0.0 1.0 1</ambient>
                    <diffuse>0.0 0.0 1.0 1</diffuse>
                <lighting>1</lighting>
                </material>
            </visual>
            </link>

            <link name='Prop_4'>
            <inertial>
                <mass>1e-6</mass>
                <inertia>
                <ixx>1e-9</ixx>
                <ixy>0</ixy>
                <ixz>0</ixz>
                <iyy>1e-9</iyy>
                <iyz>0</iyz>
                <izz>1e-9</izz>
                </inertia>
                <pose>0 0 0 0 0 0</pose>
            </inertial>
            <pose>72.6e-3 86.6e-3 28.0e-3 0 0 0</pose>
            <gravity>1</gravity>
            <self_collide>0</self_collide>
            <visual name='SO_V5_Prop_3'>
                <pose>0 0 0 0 0 0</pose>
                <geometry>
                <mesh>
                    <uri>models/Source_One_V5/SAR_Base/meshes/SO_V5_Propeller.STL</uri>
                    <scale>1 1 1</scale>
                </mesh>
                </geometry>
                <material>
                    <!--Blue-->
                    <ambient>0.0 0.0 1.0 1</ambient>
                    <diffuse>0.0 0.0 1.0 1</diffuse>
                <lighting>1</lighting>
                </material>
            </visual>
            </link>

            <link name='Camera'>
                <inertial>
                    <mass>1e-6</mass>
                    <inertia>
                    <ixx>1e-9</ixx>
                    <ixy>0</ixy>
                    <ixz>0</ixz>
                    <iyy>1e-9</iyy>
                    <iyz>0</iyz>
                    <izz>1e-9</izz>
                    </inertia>
                    <pose>0 0 0 0 0 0</pose>
                </inertial>


            </link>

            <joint name='Prop_1_Joint' type='revolute'>
            <parent>SAR_Body</parent>
            <child>Prop_1</child>
            <pose>0 0 0 0 0 0</pose>
            <axis>
                <xyz>0 0 1</xyz>
                <limit>
                <lower>-1.79769e+308</lower>
                <upper>1.79769e+308</upper>
                <effort>-1</effort>
                <velocity>-1</velocity>
                </limit>
                <dynamics>
                <spring_reference>0</spring_reference>
                <spring_stiffness>0</spring_stiffness>
                </dynamics>
            </axis>
            </joint>

            <joint name='Prop_2_Joint' type='revolute'>
            <parent>SAR_Body</parent>
            <child>Prop_2</child>
            <pose>0 0 0 0 0 0</pose>
            <axis>
                <xyz>0 0 1</xyz>
                <limit>
                <lower>-1.79769e+308</lower>
                <upper>1.79769e+308</upper>
                <effort>-1</effort>
                <velocity>-1</velocity>
                </limit>
                <dynamics>
                <spring_reference>0</spring_reference>
                <spring_stiffness>0</spring_stiffness>
                </dynamics>
            </axis>
            </joint>

            <joint name='Prop_3_Joint' type='revolute'>
            <parent>SAR_Body</parent>
            <child>Prop_3</child>
            <pose>0 0 0 0 0 0</pose>
            <axis>
                <xyz>0 0 1</xyz>
                <limit>
                <lower>-1.79769e+308</lower>
                <upper>1.79769e+308</upper>
                <effort>-1</effort>
                <velocity>-1</velocity>
                </limit>
                <dynamics>
                <spring_reference>0</spring_reference>
                <spring_stiffness>0</spring_stiffness>
                </dynamics>
            </axis>
            </joint>

            <joint name='Prop_4_Joint' type='revolute'>
            <parent>SAR_Body</parent>
            <child>Prop_4</child>
            <pose>0 0 0 0 0 0</pose>
            <axis>
                <xyz>0 0 1</xyz>
                <limit>
                <lower>-1.79769e+308</lower>
                <upper>1.79769e+308</upper>
                <effort>-1</effort>
                <velocity>-1</velocity>
                </limit>
                <dynamics>
                <spring_reference>0</spring_reference>
                <spring_stiffness>0</spring_stiffness>
                </dynamics>
            </axis>
            </joint>
          
            <plugin
                filename="/home/dlee/ros2_ws/install/sar_gazebo/lib/libImu_Plugin.so"
                name="gz::sim::systems::Imu_Plugin">
            </plugin>
            
            <plugin
                filename="/home/dlee/ros2_ws/install/sar_gazebo/lib/libVicon_Plugin.so"
                name="gz::sim::systems::Vicon_Plugin">
                <link_name>SAR_Body</link_name>
            </plugin>
<!--  -->
            <plugin
                filename="/home/dlee/ros2_ws/install/sar_gazebo/lib/libMotor_Plugin.so"
                name="gz::sim::systems::Motor_Plugin">
                <Motor_Number>1</Motor_Number>
                <joint_name>Prop_1_Joint</joint_name>
                <link_name>Prop_1</link_name>
                <canonicallink_name>SAR_Body</canonicallink_name>
                <Turning_Direction>ccw</Turning_Direction>
                <Visual_Slowdown>200</Visual_Slowdown>                
            </plugin>

            <plugin
                filename="/home/dlee/ros2_ws/install/sar_gazebo/lib/libMotor_Plugin.so"
                name="gz::sim::systems::Motor_Plugin">
                <Motor_Number>2</Motor_Number>
                <joint_name>Prop_2_Joint</joint_name>
                <link_name>Prop_2</link_name>
                <canonicallink_name>SAR_Body</canonicallink_name>
                <Turning_Direction>cw</Turning_Direction>
                <Visual_Slowdown>200</Visual_Slowdown>                  
            </plugin>
            
            <plugin
                filename="/home/dlee/ros2_ws/install/sar_gazebo/lib/libMotor_Plugin.so"
                name="gz::sim::systems::Motor_Plugin">
                <Motor_Number>3</Motor_Number>
                <joint_name>Prop_3_Joint</joint_name>
                <link_name>Prop_3</link_name>
                <canonicallink_name>SAR_Body</canonicallink_name>
                <Turning_Direction>ccw</Turning_Direction>
                <Visual_Slowdown>200</Visual_Slowdown>                  
            </plugin>

            <plugin
                filename="/home/dlee/ros2_ws/install/sar_gazebo/lib/libMotor_Plugin.so"
                name="gz::sim::systems::Motor_Plugin">
                <Motor_Number>4</Motor_Number>
                <joint_name>Prop_4_Joint</joint_name>
                <link_name>Prop_4</link_name>
                <canonicallink_name>SAR_Body</canonicallink_name>
                <Turning_Direction>cw</Turning_Direction>
                <Visual_Slowdown>200</Visual_Slowdown>               
            </plugin>

        </model>
    </world>
</sdf>
